<?xml version="1.0" encoding="UTF-8"?>

<robot xmlns:xacro="http://www.ros.org/wiki/xacro" name="new_robot">

    xacro: <xacro:include filename="$(find robot_description)/urdf/plugin.gazebo"/>

    <link name="link_base"/>
    <link name="chassis">
        <inertial>
            <origin xyz="0.0 0.0 0.0" rpy="0.0 0.0 0.0"/>
            <mass value="8.0"/>
            <inertia ixx="0.1633" ixy="0.0" ixz="0.0" iyy="0.1733" iyz="0.0" izz="0.2733"/>
        </inertial>
        <visual name="">
            <origin xyz="0.0 0.0 0.0" rpy="0.0 0.0 0.0"/>
            <geometry>
                <box size="0.50 0.40 0.10"/>
            </geometry>
            <material name="">
                <color rgba="1.0 0.0 1.0 1.0"/>
                <texture filename=""/>
            </material>
        </visual>
        <collision>
            <origin xyz="0.0 0.0 0.0" rpy="0.0 0.0 0.0"/>
            <geometry>
                <box size="0.50 0.40 0.20"/>
            </geometry>
        </collision>
    </link>


    <joint name="footjoint" type="fixed">
        <parent link="link_base"/>
        <child link="chassis"/>
        <origin rpy="0 0 0" xyz="0 0.0 0"/>
      </joint>


    <link name="front_left_wheel">
        <inertial>
            <origin xyz="0.0 0.0 0.0" rpy="0.0 0.0 0.0"/>
            <mass value="0.10"/>
            <inertia ixx="00.00027" ixy="0.0" ixz="0.0" iyy="00.00027" iyz="0.0" izz="0.00025"/>
        </inertial>
        <visual name="">
            <origin xyz="0.0 0.0 0.0" rpy="1.57079632679 0.0 0.0"/>
            <geometry>
                <cylinder radius="0.10" length="0.05"/>
            </geometry>
            <material name="">
                <color rgba="1.0 0.0 0.0 1.0"/>
                <texture filename=""/>
            </material>
        </visual>
        <collision>
            <origin xyz="0.0 0.0 0.0" rpy="1.57079632679 0.0 0.0"/>
            <geometry>
                <cylinder radius="0.10" length="0.05"/>
            </geometry>
        </collision>
    </link>

    <joint name="joint_front_left_wheel" type="continuous">
        <origin xyz="0.2 0.225 0.0" rpy="0.0 0.0 0.0"/>
        <parent link="chassis"/>
        <child link="front_left_wheel"/>
        <axis xyz="0.0 1.0 0.0"/>
        <limit lower="0.0" upper="0.0" effort="0.0" velocity="0.0"/>
    </joint>
<!--right -->
    <link name="front_rigth_wheel">
        <inertial>
            <origin xyz="0.0 0.0 0.0" rpy="0.0 0.0 0.0"/>
            <mass value="0.10"/>
            <inertia ixx="00.00027" ixy="0.0" ixz="0.0" iyy="00.00027" iyz="0.0" izz="0.00025"/>
        </inertial>
        <visual name="">
            <origin xyz="0.0 0.0 0.0" rpy="1.57079632679 0.0 0.0"/>
            <geometry>
                <cylinder radius="0.10" length="0.05"/>
            </geometry>
            <material name="">
                <color rgba="1.0 0.0 0.0 1.0"/>
                <texture filename=""/>
            </material>
        </visual>
        <collision>
            <origin xyz="0.0 0.0 0.0" rpy="1.57079632679 0.0 0.0"/>
            <geometry>
                <cylinder radius="0.10" length="0.05"/>
            </geometry>
        </collision>
    </link>

    <joint name="joint_front_right_wheel" type="continuous">
        <origin xyz="0.2 -0.225 0.0" rpy="0.0 0.0 0.0"/>
        <parent link="chassis"/>
        <child link="front_rigth_wheel"/>
        <axis xyz="0.0 1.0 0.0"/>
        <limit lower="0.0" upper="0.0" effort="0.0" velocity="0.0"/>
    </joint>
    
    <link name="rear_left_wheel">
        <inertial>
            <origin xyz="0.0 0.0 0.0" rpy="0.0 0.0 0.0"/>
            <mass value="0.10"/>
            <inertia ixx="00.00027" ixy="0.0" ixz="0.0" iyy="00.00027" iyz="0.0" izz="0.00025"/>
        </inertial>
        <visual name="">
            <origin xyz="0.0 0.0 0.0" rpy="1.57079632679 0.0 0.0"/>
            <geometry>
                <cylinder radius="0.10" length="0.05"/>
            </geometry>
            <material name="">
                <color rgba="1.0 0.0 0.0 1.0"/>
                <texture filename=""/>
            </material>
        </visual>
        <collision>
            <origin xyz="0.0 0.0 0.0" rpy="1.57079632679 0.0 0.0"/>
            <geometry>
                <cylinder radius="0.10" length="0.05"/>
            </geometry>
        </collision>
    </link>

    <joint name="joint_rear_left_wheel" type="continuous">
        <origin xyz="-0.2 0.225 0.0" rpy="0.0 0.0 0.0"/>
        <parent link="chassis"/>
        <child link="rear_left_wheel"/>
        <axis xyz="0.0 01.0 0.0"/>
        <limit lower="0.0" upper="0.0" effort="0.0" velocity="0.0"/>
    </joint>
<!--right -->
    <link name="rear_rigth_wheel">
        <inertial>
            <origin xyz="0.0 0.0 0.0" rpy="0.0 0.0 0.0"/>
            <mass value="0.10"/>
            <inertia ixx="00.00027" ixy="0.0" ixz="0.0" iyy="00.00027" iyz="0.0" izz="0.00025"/>
        </inertial>
        <visual name="">
            <origin xyz="0.0 0.0 0.0" rpy="1.57079632679 0.0 0.0"/>
            <geometry>
                <cylinder radius="0.10" length="0.05"/>
            </geometry>
            <material name="">
                <color rgba="1.0 0.0 0.0 1.0"/>
                <texture filename=""/>
            </material>
        </visual>
        <collision>
            <origin xyz="0.0 0.0 0.0" rpy="1.57079632679 0.0 0.0"/>
            <geometry>
                <cylinder radius="0.10" length="0.05"/>
            </geometry>
        </collision>
    </link>

    <joint name="joint_rear_right_wheel" type="continuous">
        <origin xyz="-0.2 -0.225 0.0" rpy="0.0 0.0 0.0"/>
        <parent link="chassis"/>
        <child link="rear_rigth_wheel"/>
        <axis xyz="0.0 1.0 0.0"/>
        <limit lower="0.0" upper="0.0" effort="0.0" velocity="0.0"/>
    </joint>

    <link name="camera">
        <inertial>
            <origin xyz="0.0 0.0 0.0" rpy="0.0 0.0 0.0"/>
            <mass value="0.1e-5"/>
            <inertia ixx="1e-6" ixy="0" ixz="0" iyy="1e-6" iyz="0" izz="1e-6"/>
        </inertial>
        <visual name="">
            <origin xyz="0.0 0.0 0.0" rpy="0.0 0.0 0.0"/>
            <geometry>
                <box size="0.02 0.2 0.02"/>
            </geometry>
            <material name="">
                <color rgba="0.30 0.30 0.30 1.0"/>
                <texture filename=""/>
            </material>
        </visual>
        <collision>
            <origin xyz="0.0 0.0 0.0" rpy="0.0 0.0 0.0"/>
            <geometry>
                <box size="0.02 0.20 0.02"/>
            </geometry>
        </collision>
    </link>

    <joint name="joint_camera" type="fixed">
        <origin xyz="0.251 0.0 0.0" rpy="0.0 0.0 0.0"/>
        <parent link="chassis"/>
        <child link="camera"/>
        <axis xyz="0.0 1.0 0.0"/>
        <limit lower="0.0" upper="0.0" effort="0.0" velocity="0.0"/>
    </joint>

    <link name="lidar">
        <inertial>
            <origin xyz="0.0 0.0 0.0" rpy="0.0 0.0 0.0"/>
            <mass value="0.01"/>
            <inertia ixx="1e-6" ixy="0" ixz="0" iyy="1e-6" iyz="0" izz="1e-6"/>
        </inertial>
        <visual name="">
            <origin xyz="0.0 0.0 0.0" rpy="0.0 0.0 0.0"/>
            <geometry>
                <cylinder radius="0.025" length="0.05"/>
            </geometry>
            <material name="">
                <color rgba="1.0 0.0 0.0 1.0"/>
                <texture filename=""/>
            </material>
        </visual>
        <collision>
            <origin xyz="0.0 0.0 0.0" rpy="0.0 0.0 0.0"/>
            <geometry>
                <cylinder radius="0.025" length="0.05"/>
            </geometry>
        </collision>
    </link>

    <joint name="joint_lidar" type="fixed">
        <origin xyz="0.21 0.0 0.0625" rpy="0.0 0.0 0.0"/>
        <parent link="chassis"/>
        <child link="lidar"/>
        <axis xyz="0.0 0.0 0.0"/>
        <limit lower="0.0" upper="0.0" effort="0.0" velocity="0.0"/>
    </joint>

</robot>
